Workbook
Name UPDATE: 'Data Sheet'!$E$1

Sheet FINANCIALS >

Sheet About
B3: About The Company
B5: HDFC Bank Limited (also known as HDFC) is an Indian banking and financial services company headquartered in Mumbai. It is India's largest private sector bank by assets and the world's tenth-largest bank by market capitalization as of May 2024.
B8: Key Points
B10: Market Position
B11: The company is India's one of 3 systemically important banks with a 15% market share in the banking sector’s advances and a 37% market share in the private sector banks’ advances as of FY24. It is also the second-largest bank in India. It is among the top 3 Government Banks collecting direct and indirect taxes for the Government of India. It is a market leader in almost every asset category.
B15: Key Ratios Q3 FY26 | C15: HDFC | D15: Industry Avg
B16: Capital Adequacy Ratio: | C16: 0.199 | D16: 0.177
B17: NIM: | C17: 0.035 | D17: 0.033
B18: Gross NPA: | C18: 0.012 | D18: 0.018
B19: Net NPA: | C19: 0.004 | D19: 0.005
B20: Cost to Income ratio: | C20: 0.392 | D20: 0.45
B21: ROA: | C21: 0.019 | D21: 0.012
B23: Amalgamation
B24: In July 2023, HDFC bank completed its amalgamation with its promoter, HDFC Ltd. With this merger, the bank now operates across various segments, including banking, insurance (through HDFC Life Insurance and HDFC Ergo General Insurance), and asset management (via HDFC Asset Management).
B29: Focus
B30: The bank focuses on growing its CASA mix by bringing new customers. It maintains the objectives of profitable growth.
B33: Financial Snapshot
B35: Market Cap | C35: ₹ 11,11,989 Cr. | E35: ROE | F35: 0.136
B36: Current Price | C36: ₹ 721 | E36: Face Value | F36: ₹ 1.00
B37: High / Low | C37: ₹ 1,020 / 698 | E37: Profit growth | F37: 0.12
B38: Stock P/E | C38: 13.7 | E38: No. of Share Holders | F38: 45,32,753
B39: Book Value | C39: ₹ 390 | E39: No. Eq. Shares | F39: 1541
B40: Dividend Yield | C40: 0.0184 | E40: EBITDA | F40: ₹ 2,93,893 Cr.
B41: ROCE | C41: 0.0702
B44: Asset quality remained resilient: Despite the significant expansion in HDFC Bank’s loan book following the HDFC Ltd merger, asset quality remained resilient, with Gross NPA and Net NPA remaining controlled. Maintaining asset quality while expanding the post-merger balance sheet will remain important for sustaining profitability.
B48: Capital position remained strong: HDFC Bank maintained a strong capital position, providing sufficient capacity to absorb the HDFC Ltd merger and continue supporting credit growth without major capital constraints.

Sheet Historical FS
B6: ="Historical Financial Statement - "& 'Data Sheet'!B1 -> Historical Financial Statement - HDFC BANK LTD
B7: Years | C7: ='Data Sheet'!D16 -> 43555 | D7: ='Data Sheet'!E16 -> 43921 | E7: ='Data Sheet'!F16 -> 44286 | F7: ='Data Sheet'!G16 -> 44651 | G7: ='Data Sheet'!H16 -> 45016 | H7: ='Data Sheet'!I16 -> 45382 | I7: ='Data Sheet'!J16 -> 45747 | J7: ='Data Sheet'!K16 -> 46112
A8: # | B8: Income Statement
B9: Sales | C9: =IFERROR('Data Sheet'!D17,0) -> 105160.74 | D9: =IFERROR('Data Sheet'!E17,0) -> 122189.29 | E9: =IFERROR('Data Sheet'!F17,0) -> 128552.4 | F9: =IFERROR('Data Sheet'!G17,0) -> 135936.41 | G9: =IFERROR('Data Sheet'!H17,0) -> 170754.05 | H9: =IFERROR('Data Sheet'!I17,0) -> 283649.02 | I9: =IFERROR('Data Sheet'!J17,0) -> 336367.43 | J9: =IFERROR('Data Sheet'!K17,0) -> 348615.15
B10: Sales Growth | C10: - | D10: =D9/C9-1 -> 0.16192878 | E10: =E9/D9-1 -> 0.052075841 | F10: =F9/E9-1 -> 0.05743969 | G10: =G9/F9-1 -> 0.25613182 | H10: =H9/G9-1 -> 0.66115545 | I10: =I9/H9-1 -> 0.1858579 | J10: =J9/I9-1 -> 0.03641173
B12: COGS | C12: =IFERROR(SUM('Data Sheet'!D20:D22,'Data Sheet'!D18)-(1*'Data Sheet'!D19),0) -> 11738.28 | D12: =IFERROR(SUM('Data Sheet'!E20:E22,'Data Sheet'!E18)-(1*'Data Sheet'!E19),0) -> 14217.54 | E12: =IFERROR(SUM('Data Sheet'!F20:F22,'Data Sheet'!F18)-(1*'Data Sheet'!F19),0) -> 15331.46 | F12: =IFERROR(SUM('Data Sheet'!G20:G22,'Data Sheet'!G18)-(1*'Data Sheet'!G19),0) -> 17677.08 | G12: =IFERROR(SUM('Data Sheet'!H20:H22,'Data Sheet'!H18)-(1*'Data Sheet'!H19),0) -> 22207.86 | H12: =IFERROR(SUM('Data Sheet'!I20:I22,'Data Sheet'!I18)-(1*'Data Sheet'!I19),0) -> 34305.82 | I12: =IFERROR(SUM('Data Sheet'!J20:J22,'Data Sheet'!J18)-(1*'Data Sheet'!J19),0) -> 38111.45 | J12: =IFERROR(SUM('Data Sheet'!K20:K22,'Data Sheet'!K18)-(1*'Data Sheet'!K19),0) -> 42336.45
B13: COGS as %of sales | C13: =C12/C9 -> 0.11162227 | D13: =D12/D9 -> 0.11635668 | E13: =E12/E9 -> 0.11926234 | F13: =F12/F9 -> 0.13003933 | G13: =G12/G9 -> 0.13005759 | H13: =H12/H9 -> 0.12094461 | I13: =I12/I9 -> 0.11330303 | J13: =J12/J9 -> 0.1214418
B15: Gross Profit | C15: =C9-C12 -> 93422.46 | D15: =D9-D12 -> 107971.75 | E15: =E9-E12 -> 113220.94 | F15: =F9-F12 -> 118259.33 | G15: =G9-G12 -> 148546.19 | H15: =H9-H12 -> 249343.2 | I15: =I9-I12 -> 298255.98 | J15: =J9-J12 -> 306278.7
B16: Gross profit as %of sales | C16: =C15/C9 -> 0.88837773 | D16: =D15/D9 -> 0.88364332 | E16: =E15/E9 -> 0.88073766 | F16: =F15/F9 -> 0.86996067 | G16: =G15/G9 -> 0.86994241 | H16: =H15/H9 -> 0.87905539 | I16: =I15/I9 -> 0.88669697 | J16: =J15/J9 -> 0.8785582
B18: Selling and General Expenses | C18: =IFERROR(SUM('Data Sheet'!D23:D24),0) -> 23117.99 | D18: =IFERROR(SUM('Data Sheet'!E23:E24),0) -> 31241.67 | E18: =IFERROR(SUM('Data Sheet'!F23:F24),0) -> 37125.07 | F18: =IFERROR(SUM('Data Sheet'!G23:G24),0) -> 38879.88 | G18: =IFERROR(SUM('Data Sheet'!H23:H24),0) -> 40834.44 | H18: =IFERROR(SUM('Data Sheet'!I23:I24),0) -> 139889.72 | I18: =IFERROR(SUM('Data Sheet'!J23:J24),0) -> 148863 | J18: =IFERROR(SUM('Data Sheet'!K23:K24),0) -> 161298.78
B19: S&G Exp as % of sales | C19: =C18/C9 -> 0.2198348 | D19: =D18/D9 -> 0.25568256 | E19: =E18/E9 -> 0.28879329 | F19: =F18/F9 -> 0.2860152 | G19: =G18/G9 -> 0.23914185 | H19: =H18/H9 -> 0.49317893 | I19: =I18/I9 -> 0.44256068 | J19: =J18/J9 -> 0.46268437
B21: Other Income | C21: ='Data Sheet'!D25 -> 18947.05 | D21: ='Data Sheet'!E25 -> 24878.97 | E21: ='Data Sheet'!F25 -> 27332.88 | F21: ='Data Sheet'!G25 -> 31758.99 | G21: ='Data Sheet'!H25 -> 33912.05 | H21: ='Data Sheet'!I25 -> 124345.75 | I21: ='Data Sheet'!J25 -> 134548.5 | J21: ='Data Sheet'!K25 -> 146847.66
B22: Other Income as % of sales | C22: =C21/C9 -> 0.18017228 | D22: =D21/D9 -> 0.20361007 | E22: =E21/E9 -> 0.21262053 | F22: =F21/F9 -> 0.23363123 | G22: =G21/G9 -> 0.19860173 | H22: =H21/H9 -> 0.43837892 | I22: =I21/I9 -> 0.40000454 | J22: =J21/J9 -> 0.42123144
B24: EBITDA | C24: =C15-C18+C21 -> 89251.52 | D24: =D15-D18+D21 -> 101609.05 | E24: =E15-E18+E21 -> 103428.75 | F24: =F15-F18+F21 -> 111138.44 | G24: =G15-G18+G21 -> 141623.8 | H24: =H15-H18+H21 -> 233799.23 | I24: =I15-I18+I21 -> 283941.48 | J24: =J15-J18+J21 -> 291827.58
B25: EBITA as %of sales | C25: =C24/C9 -> 0.84871521 | D25: =D24/D9 -> 0.83157084 | E25: =E24/E9 -> 0.80456491 | F25: =F24/F9 -> 0.81757669 | G25: =G24/G9 -> 0.82940229 | H25: =H24/H9 -> 0.82425538 | I25: =I24/I9 -> 0.84414083 | J25: =J24/J9 -> 0.83710527
B27: Interest | C27: =IFERROR('Data Sheet'!D27,0) -> 53712.69 | D27: =IFERROR('Data Sheet'!E27,0) -> 62137.42 | E27: =IFERROR('Data Sheet'!F27,0) -> 59247.59 | F27: =IFERROR('Data Sheet'!G27,0) -> 58584.33 | G27: =IFERROR('Data Sheet'!H27,0) -> 77779.94 | H27: =IFERROR('Data Sheet'!I27,0) -> 154138.55 | I27: =IFERROR('Data Sheet'!J27,0) -> 183894.2 | J27: =IFERROR('Data Sheet'!K27,0) -> 185491.23
B28: Interest as %of sales | C28: =C27/C9 -> 0.51076752 | D28: =D27/D9 -> 0.50853409 | E28: =E27/E9 -> 0.4608828 | F28: =F27/F9 -> 0.43096864 | G28: =G27/G9 -> 0.45550861 | H28: =H27/H9 -> 0.54341295 | I28: =I27/I9 -> 0.54670632 | J28: =J27/J9 -> 0.53208023
B30: Depreciation | C30: =IFERROR('Data Sheet'!D26,0) -> 1220.67 | D30: =IFERROR('Data Sheet'!E26,0) -> 1276.77 | E30: =IFERROR('Data Sheet'!F26,0) -> 1385.01 | F30: =IFERROR('Data Sheet'!G26,0) -> 1680.73 | G30: =IFERROR('Data Sheet'!H26,0) -> 2345.47 | H30: =IFERROR('Data Sheet'!I26,0) -> 3092.08 | I30: =IFERROR('Data Sheet'!J26,0) -> 3805.23 | J30: =IFERROR('Data Sheet'!K26,0) -> 4194.9
B31: Depreciation as %of sales | C31: =C30/C9 -> 0.011607659 | D31: =D30/D9 -> 0.010449115 | E31: =E30/E9 -> 0.010773895 | F31: =F30/F9 -> 0.01236409 | G31: =G30/G9 -> 0.013735955 | H31: =H30/H9 -> 0.010901078 | I31: =I30/I9 -> 0.011312718 | J31: =J30/J9 -> 0.01203304
B33: Earnings Before Tax | C33: =C24-SUM(C27,C30) -> 34318.16 | D33: =D24-SUM(D27,D30) -> 38194.86 | E33: =E24-SUM(E27,E30) -> 42796.15 | F33: =F24-SUM(F27,F30) -> 50873.38 | G33: =G24-SUM(G27,G30) -> 61498.39 | H33: =H24-SUM(H27,H30) -> 76568.6 | I33: =I24-SUM(I27,I30) -> 96242.05 | J33: =J24-SUM(J27,J30) -> 102141.45
B34: EBT as %of sales | C34: =C33/C9 -> 0.32634004 | D34: =D33/D9 -> 0.31258763 | E34: =E33/E9 -> 0.33290821 | F34: =F33/F9 -> 0.37424396 | G34: =G33/G9 -> 0.36015772 | H34: =H33/H9 -> 0.26994135 | I34: =I33/I9 -> 0.28612179 | J34: =J33/J9 -> 0.292992
B36: Tax | C36: ='Data Sheet'!D29 -> 11872.55 | D36: ='Data Sheet'!E29 -> 10898.59 | E36: ='Data Sheet'!F29 -> 10939.38 | F36: ='Data Sheet'!G29 -> 12722.48 | G36: ='Data Sheet'!H29 -> 15349.69 | H36: ='Data Sheet'!I29 -> 11122.1 | I36: ='Data Sheet'!J29 -> 22801.88 | J36: ='Data Sheet'!K29 -> 22921.99
B37: Effective Tax Rate | C37: =C36/C33 -> 0.34595532 | D37: =D36/D33 -> 0.2853418 | E37: =E36/E33 -> 0.25561598 | F37: =F36/F33 -> 0.25008128 | G37: =G36/G33 -> 0.24959499 | H37: =H36/H33 -> 0.14525667 | I37: =I36/I33 -> 0.23692222 | J37: =J36/J33 -> 0.22441418
B39: Net Profit | C39: =C33-C36 -> 22445.61 | D39: =D33-D36 -> 27296.27 | E39: =E33-E36 -> 31856.77 | F39: =F33-F36 -> 38150.9 | G39: =G33-G36 -> 46148.7 | H39: =H33-H36 -> 65446.5 | I39: =I33-I36 -> 73440.17 | J39: =J33-J36 -> 79219.46
B40: Net Margins | C40: =C39/C9 -> 0.21344097 | D40: =D39/D9 -> 0.22339331 | E40: =E39/E9 -> 0.24781155 | F40: =F39/F9 -> 0.28065255 | G40: =G39/G9 -> 0.27026416 | H40: =H39/H9 -> 0.23073057 | I40: =I39/I9 -> 0.21833318 | J40: =J39/J9 -> 0.22724044
B42: No. Of equity shares | C42: =IFERROR('Data Sheet'!B93,0) -> 1025.02 | D42: =IFERROR('Data Sheet'!C93,0) -> 1038.04 | E42: =IFERROR('Data Sheet'!D93,0) -> 1089.32 | F42: =IFERROR('Data Sheet'!E93,0) -> 1096.66 | G42: =IFERROR('Data Sheet'!F93,0) -> 1102.56 | H42: =IFERROR('Data Sheet'!G93,0) -> 1109.11 | I42: =IFERROR('Data Sheet'!H93,0) -> 1115.95 | J42: =IFERROR('Data Sheet'!I93,0) -> 1519.38
B44: Earning per share | C44: =IFERROR(C39/C42,0) -> 21.897729 | D44: =IFERROR(D39/D42,0) -> 26.295971 | E44: =IFERROR(E39/E42,0) -> 29.244639 | F44: =IFERROR(F39/F42,0) -> 34.788266 | G44: =IFERROR(G39/G42,0) -> 41.855953 | H44: =IFERROR(H39/H42,0) -> 59.008124 | I44: =IFERROR(I39/I42,0) -> 65.809552 | J44: =IFERROR(J39/J42,0) -> 52.139333
B45: EPS Growth% | D45: =IFERROR(D44/C44-1,0) -> 0.20085382 | E45: =IFERROR(E44/D44-1,0) -> 0.11213382 | F45: =IFERROR(F44/E44-1,0) -> 0.18956046 | G45: =IFERROR(G44/F44-1,0) -> 0.20316296 | H45: =IFERROR(H44/G44-1,0) -> 0.40979046 | I45: =IFERROR(I44/H44-1,0) -> 0.11526258 | J45: =IFERROR(J44/I44-1,0) -> -0.20772394
B47: Dividend Per share | C47: =IFERROR('Data Sheet'!D31/C42,0) -> 3.9852393 | D47: =IFERROR('Data Sheet'!E31/D42,0) -> 1.3205849 | E47: =IFERROR('Data Sheet'!F31/E42,0) -> 3.2895017 | F47: =IFERROR('Data Sheet'!G31/F42,0) -> 7.8379078 | G47: =IFERROR('Data Sheet'!H31/G42,0) -> 9.6152862 | H47: =IFERROR('Data Sheet'!I31/H42,0) -> 13.356619 | I47: =IFERROR('Data Sheet'!J31/I42,0) -> 15.085658 | J47: =IFERROR('Data Sheet'!K31/J42,0) -> 15.703623 | M47: In the FY 25-26 review HDFC Bank issued its first ever bonus equity shares in the proportion of 1:1. Total dividend per equity share for the Financial Year 2025-26 is H15.50 including special interim dividend of H2.50 per equity share (adj. for bonus)
B48: Dividend payout ratio | C48: =IFERROR(C47/C44,0) -> 0.18199327 | D48: =IFERROR(D47/D44,0) -> 0.050220048 | E48: =IFERROR(E47/E44,0) -> 0.11248221 | F48: =IFERROR(F47/F44,0) -> 0.2253032 | G48: =IFERROR(G47/G44,0) -> 0.22972326 | H48: =IFERROR(H47/H44,0) -> 0.22635221 | I48: =IFERROR(I47/I44,0) -> 0.22923204 | J48: =IFERROR(J47/J44,0) -> 0.30118572
B50: Retained Earnings | C50: =IFERROR(IF(C44>C47,1-C48,0),0) -> 0.81800673 | D50: =IFERROR(IF(D44>D47,1-D48,0),0) -> 0.94977995 | E50: =IFERROR(IF(E44>E47,1-E48,0),0) -> 0.88751779 | F50: =IFERROR(IF(F44>F47,1-F48,0),0) -> 0.7746968 | G50: =IFERROR(IF(G44>G47,1-G48,0),0) -> 0.77027674 | H50: =IFERROR(IF(H44>H47,1-H48,0),0) -> 0.77364779 | I50: =IFERROR(IF(I44>I47,1-I48,0),0) -> 0.77076796 | J50: =IFERROR(IF(J44>J47,1-J48,0),0) -> 0.69881428
B53: Strong long-term growth: Net profit increased from ₹22,446 Cr in FY19 to ₹79,220 Cr in FY26, indicating strong earnings growth over the period.
B54: FY24 was a major inflection point: Revenue increased by 66.1%, primarily due to the HDFC Ltd–HDFC Bank merger, which significantly increased the scale of operations.
B55: Post-merger normalization: Revenue growth moderated from 18.6% in FY25 to 3.6% in FY26, indicating normalization after the merger-led jump in FY24.
B56: Profitability remains strong: Despite margin compression after the merger, net profit continued to rise, with FY26 net margin improving to 22.7% from 21.8% in FY25.
B57: Higher interest cost is a key pressure: Interest expense increased significantly post-merger, reflecting the larger funding base and continued cost of mobilizing deposits.
B58: Operating expenses increased sharply: Higher expenses in FY24 reflect the larger combined business, branch expansion, employee costs and integration-related requirements.
B59: Merger synergies: The combination provides opportunities for mortgage + banking cross-selling, higher deposit penetration, wider distribution and faster home-loan processing.
B60: EPS decline needs context: FY26 EPS fell despite higher net profit, mainly because the number of shares increased substantially, so the EPS decline does not by itself indicate weaker underlying profitability.
A63: # | B63: Balance Sheet
...

Sheet Ratio Analysis
B2: ="Ratio Analysis"&" " & "-" & " " &'Data Sheet'!B1 -> Ratio Analysis - HDFC BANK LTD
B3: Years | C3: ='Historical FS'!C7 -> 43555 | D3: ='Historical FS'!D7 -> 43921 | E3: ='Historical FS'!E7 -> 44286 | F3: ='Historical FS'!F7 -> 44651 | G3: ='Historical FS'!G7 -> 45016 | H3: ='Historical FS'!H7 -> 45382 | I3: ='Historical FS'!I7 -> 45747 | J3: ='Historical FS'!J7 -> 46112 | K3: Trend | L3: Mean | M3: Median
B5: Sales Growth | C5: =IFERROR('Historical FS'!C10,0) -> - | D5: =IFERROR('Historical FS'!D10,0) -> 0.16192878 | E5: =IFERROR('Historical FS'!E10,0) -> 0.052075841 | F5: =IFERROR('Historical FS'!F10,0) -> 0.05743969 | G5: =IFERROR('Historical FS'!G10,0) -> 0.25613182 | H5: =IFERROR('Historical FS'!H10,0) -> 0.66115545 | I5: =IFERROR('Historical FS'!I10,0) -> 0.1858579 | J5: =IFERROR('Historical FS'!J10,0) -> 0.03641173 | L5: =AVERAGE(D5:J5) -> 0.2015716 | M5: =MEDIAN(D5:J5) -> 0.16192878
B6: EBITDA Growth | D6: =IFERROR(('Historical FS'!D24-'Historical FS'!C24)/'Historical FS'!D24,0) -> 0.1216184 | E6: =IFERROR(('Historical FS'!E24-'Historical FS'!D24)/'Historical FS'!E24,0) -> 0.017593754 | F6: =IFERROR(('Historical FS'!F24-'Historical FS'!E24)/'Historical FS'!F24,0) -> 0.069370148 | G6: =IFERROR(('Historical FS'!G24-'Historical FS'!F24)/'Historical FS'!G24,0) -> 0.21525591 | H6: =IFERROR(('Historical FS'!H24-'Historical FS'!G24)/'Historical FS'!H24,0) -> 0.39425036 | I6: =IFERROR(('Historical FS'!I24-'Historical FS'!H24)/'Historical FS'!I24,0) -> 0.17659361 | J6: =IFERROR(('Historical FS'!J24-'Historical FS'!I24)/'Historical FS'!J24,0) -> 0.027023148 | L6: =AVERAGE(D6:J6) -> 0.1459579 | M6: =MEDIAN(D6:J6) -> 0.1216184
B7: EBIT Growth | D7: =IFERROR((('Historical FS'!D24-'Historical FS'!D30)-('Historical FS'!C24-'Historical FS'!C30))/('Historical FS'!C24-'Historical FS'!C30),0) -> 0.13973999 | E7: =IFERROR((('Historical FS'!E24-'Historical FS'!E30)-('Historical FS'!D24-'Historical FS'!D30))/('Historical FS'!D24-'Historical FS'!D30),0) -> 0.01705792 | F7: =IFERROR((('Historical FS'!F24-'Historical FS'!F30)-('Historical FS'!E24-'Historical FS'!E30))/('Historical FS'!E24-'Historical FS'!E30),0) -> 0.072654824 | G7: =IFERROR((('Historical FS'!G24-'Historical FS'!G30)-('Historical FS'!F24-'Historical FS'!F30))/('Historical FS'!F24-'Historical FS'!F30),0) -> 0.27243965 | H7: =IFERROR((('Historical FS'!H24-'Historical FS'!H30)-('Historical FS'!G24-'Historical FS'!G30))/('Historical FS'!G24-'Historical FS'!G30),0) -> 0.65644684 | I7: =IFERROR((('Historical FS'!I24-'Historical FS'!I30)-('Historical FS'!H24-'Historical FS'!H30))/('Historical FS'!H24-'Historical FS'!H30),0) -> 0.2142504 | J7: =IFERROR((('Historical FS'!J24-'Historical FS'!J30)-('Historical FS'!I24-'Historical FS'!I30))/('Historical FS'!I24-'Historical FS'!I30),0) -> 0.026759943 | L7: =AVERAGE(D7:J7) -> 0.19990708 | M7: =MEDIAN(D7:J7) -> 0.13973999
B8: Net Profit Growth | D8: =IFERROR('Historical FS'!D39/'Historical FS'!C39-1,0) -> 0.21610729 | E8: =IFERROR('Historical FS'!E39/'Historical FS'!D39-1,0) -> 0.16707411 | F8: =IFERROR('Historical FS'!F39/'Historical FS'!E39-1,0) -> 0.1975759 | G8: =IFERROR('Historical FS'!G39/'Historical FS'!F39-1,0) -> 0.20963595 | H8: =IFERROR('Historical FS'!H39/'Historical FS'!G39-1,0) -> 0.41816563 | I8: =IFERROR('Historical FS'!I39/'Historical FS'!H39-1,0) -> 0.12214053 | J8: =IFERROR('Historical FS'!J39/'Historical FS'!I39-1,0) -> 0.078693854 | L8: =AVERAGE(D8:J8) -> 0.20134189 | M8: =MEDIAN(D8:J8) -> 0.1975759
B9: Dividend Growth | D9: =IFERROR('Historical FS'!D47/'Historical FS'!C47-1,0) -> -0.66863095 | E9: =IFERROR('Historical FS'!E47/'Historical FS'!D47-1,0) -> 1.4909429 | F9: =IFERROR('Historical FS'!F47/'Historical FS'!E47-1,0) -> 1.3827037 | G9: =IFERROR('Historical FS'!G47/'Historical FS'!F47-1,0) -> 0.22676695 | H9: =IFERROR('Historical FS'!H47/'Historical FS'!G47-1,0) -> 0.38910262 | I9: =IFERROR('Historical FS'!I47/'Historical FS'!H47-1,0) -> 0.12945182 | J9: =IFERROR('Historical FS'!J47/'Historical FS'!I47-1,0) -> 0.040963714 | L9: =AVERAGE(D9:J9) -> 0.42732868 | M9: =MEDIAN(D9:J9) -> 0.22676695
B11: Gross Margin | D11: =IFERROR('Historical FS'!C16,0) -> 0.88837773 | E11: =IFERROR('Historical FS'!D16,0) -> 0.88364332 | F11: =IFERROR('Historical FS'!E16,0) -> 0.88073766 | G11: =IFERROR('Historical FS'!F16,0) -> 0.86996067 | H11: =IFERROR('Historical FS'!G16,0) -> 0.86994241 | I11: =IFERROR('Historical FS'!H16,0) -> 0.87905539 | J11: =IFERROR('Historical FS'!I16,0) -> 0.88669697 | L11: =AVERAGE(D11:J11) -> 0.87977345 | M11: =MEDIAN(D11:J11) -> 0.88073766
B12: EBITDA Margin | D12: =IFERROR('Historical FS'!C25,0) -> 0.84871521 | E12: =IFERROR('Historical FS'!D25,0) -> 0.83157084 | F12: =IFERROR('Historical FS'!E25,0) -> 0.80456491 | G12: =IFERROR('Historical FS'!F25,0) -> 0.81757669 | H12: =IFERROR('Historical FS'!G25,0) -> 0.82940229 | I12: =IFERROR('Historical FS'!H25,0) -> 0.82425538 | J12: =IFERROR('Historical FS'!I25,0) -> 0.84414083 | L12: =AVERAGE(D12:J12) -> 0.82860373 | M12: =MEDIAN(D12:J12) -> 0.82940229
B13: EBIT Margin | D13: =IFERROR(('Historical FS'!C24-'Historical FS'!C30)/'Historical FS'!C9,0) -> 0.83710756 | E13: =IFERROR(('Historical FS'!D24-'Historical FS'!D30)/'Historical FS'!D9,0) -> 0.82112172 | F13: =IFERROR(('Historical FS'!E24-'Historical FS'!E30)/'Historical FS'!E9,0) -> 0.79379101 | G13: =IFERROR(('Historical FS'!F24-'Historical FS'!F30)/'Historical FS'!F9,0) -> 0.8052126 | H13: =IFERROR(('Historical FS'!G24-'Historical FS'!G30)/'Historical FS'!G9,0) -> 0.81566633 | I13: =IFERROR(('Historical FS'!H24-'Historical FS'!H30)/'Historical FS'!H9,0) -> 0.8133543 | J13: =IFERROR(('Historical FS'!I24-'Historical FS'!I30)/'Historical FS'!I9,0) -> 0.83282811 | L13: =AVERAGE(D13:J13) -> 0.81701166 | M13: =MEDIAN(D13:J13) -> 0.81566633
B14: EBT Margin | D14: =IFERROR('Historical FS'!C34,0) -> 0.32634004 | E14: =IFERROR('Historical FS'!D34,0) -> 0.31258763 | F14: =IFERROR('Historical FS'!E34,0) -> 0.33290821 | G14: =IFERROR('Historical FS'!F34,0) -> 0.37424396 | H14: =IFERROR('Historical FS'!G34,0) -> 0.36015772 | I14: =IFERROR('Historical FS'!H34,0) -> 0.26994135 | J14: =IFERROR('Historical FS'!I34,0) -> 0.28612179 | L14: =AVERAGE(D14:J14) -> 0.32318581 | M14: =MEDIAN(D14:J14) -> 0.32634004
B15: Net Profit Margin | D15: =IFERROR('Historical FS'!C40,0) -> 0.21344097 | E15: =IFERROR('Historical FS'!D40,0) -> 0.22339331 | F15: =IFERROR('Historical FS'!E40,0) -> 0.24781155 | G15: =IFERROR('Historical FS'!F40,0) -> 0.28065255 | H15: =IFERROR('Historical FS'!G40,0) -> 0.27026416 | I15: =IFERROR('Historical FS'!H40,0) -> 0.23073057 | J15: =IFERROR('Historical FS'!I40,0) -> 0.21833318 | L15: =AVERAGE(D15:J15) -> 0.2406609 | M15: =MEDIAN(D15:J15) -> 0.23073057
B17: Return on Capital Employed | D17: =IFERROR(('Historical FS'!C24-'Historical FS'!C30)/(SUM('Historical FS'!C65:C67)),0) -> 0.071343116 | E17: =IFERROR(('Historical FS'!D24-'Historical FS'!D30)/(SUM('Historical FS'!D65:D67)),0) -> 0.066471624 | F17: =IFERROR(('Historical FS'!E24-'Historical FS'!E30)/(SUM('Historical FS'!E65:E67)),0) -> 0.059285436 | G17: =IFERROR(('Historical FS'!F24-'Historical FS'!F30)/(SUM('Historical FS'!F65:F67)),0) -> 0.053859146 | H17: =IFERROR(('Historical FS'!G24-'Historical FS'!G30)/(SUM('Historical FS'!G65:G67)),0) -> 0.057348059 | I17: =IFERROR(('Historical FS'!H24-'Historical FS'!H30)/(SUM('Historical FS'!H65:H67)),0) -> 0.064734499 | J17: =IFERROR(('Historical FS'!I24-'Historical FS'!I30)/(SUM('Historical FS'!I65:I67)),0) -> 0.072437293 | L17: =AVERAGE(D17:J17) -> 0.063639882 | M17: =MEDIAN(D17:J17) -> 0.064734499
B18: Retained Earnings% | D18: =IFERROR('Historical FS'!C50,0) -> 0.81800673 | E18: =IFERROR('Historical FS'!D50,0) -> 0.94977995 | F18: =IFERROR('Historical FS'!E50,0) -> 0.88751779 | G18: =IFERROR('Historical FS'!F50,0) -> 0.7746968 | H18: =IFERROR('Historical FS'!G50,0) -> 0.77027674 | I18: =IFERROR('Historical FS'!H50,0) -> 0.77364779 | J18: =IFERROR('Historical FS'!I50,0) -> 0.77076796 | L18: =AVERAGE(D18:J18) -> 0.82067054 | M18: =MEDIAN(D18:J18) -> 0.7746968
B19: Return on Equity% | D19: =IFERROR('Historical FS'!C39/SUM('Historical FS'!C65:C66),0) -> 0.14606118 | E19: =IFERROR('Historical FS'!D39/SUM('Historical FS'!D65:D66),0) -> 0.15477699 | F19: =IFERROR('Historical FS'!E39/SUM('Historical FS'!E65:E66),0) -> 0.15183615 | G19: =IFERROR('Historical FS'!F39/SUM('Historical FS'!F65:F66),0) -> 0.15425339 | H19: =IFERROR('Historical FS'!G39/SUM('Historical FS'!G65:G66),0) -> 0.15944271 | I19: =IFERROR('Historical FS'!H39/SUM('Historical FS'!H65:H66),0) -> 0.14339873 | J19: =IFERROR('Historical FS'!I39/SUM('Historical FS'!I65:I66),0) -> 0.14074677 | L19: =AVERAGE(D19:J19) -> 0.1500737 | M19: =MEDIAN(D19:J19) -> 0.15183615
B20: Interest Coverage Ratio | D20: =IFERROR(('Historical FS'!C24-'Historical FS'!C30)/'Historical FS'!C27,0) -> 1.6389209 | E20: =IFERROR(('Historical FS'!D24-'Historical FS'!D30)/'Historical FS'!D27,0) -> 1.6146837 | F20: =IFERROR(('Historical FS'!E24-'Historical FS'!E30)/'Historical FS'!E27,0) -> 1.7223273 | G20: =IFERROR(('Historical FS'!F24-'Historical FS'!F30)/'Historical FS'!F27,0) -> 1.8683786 | H20: =IFERROR(('Historical FS'!G24-'Historical FS'!G30)/'Historical FS'!G27,0) -> 1.7906716 | I20: =IFERROR(('Historical FS'!H24-'Historical FS'!H30)/'Historical FS'!H27,0) -> 1.4967518 | J20: =IFERROR(('Historical FS'!I24-'Historical FS'!I30)/'Historical FS'!I27,0) -> 1.5233555 | L20: =AVERAGE(D20:J20) -> 1.6650128 | M20: =MEDIAN(D20:J20) -> 1.6389209

Sheet Common Size Statement
B2: ="Common Size Income Statement -" & 'Data Sheet'!B1 -> Common Size Income Statement -HDFC BANK LTD
B4: Particulars | C4: 43555 | D4: 43921 | E4: 44286 | F4: 44651 | G4: 45016 | H4: 45382 | I4: 45747 | J4: 46112
B5: Sales | C5: ='Data Sheet'!D17/'Data Sheet'!D17 -> 1 | D5: ='Data Sheet'!E17/'Data Sheet'!E17 -> 1 | E5: ='Data Sheet'!F17/'Data Sheet'!F17 -> 1 | F5: ='Data Sheet'!G17/'Data Sheet'!G17 -> 1 | G5: ='Data Sheet'!H17/'Data Sheet'!H17 -> 1 | H5: ='Data Sheet'!I17/'Data Sheet'!I17 -> 1 | I5: ='Data Sheet'!J17/'Data Sheet'!J17 -> 1 | J5: ='Data Sheet'!K17/'Data Sheet'!K17 -> 1
B6: Direct Exp | C6: ='Data Sheet'!D21/'Data Sheet'!D17 -> 0.01220541 | D6: ='Data Sheet'!E21/'Data Sheet'!E17 -> 0.010585543 | E6: ='Data Sheet'!F21/'Data Sheet'!F17 -> 0.01282831 | F6: ='Data Sheet'!G21/'Data Sheet'!G17 -> 0.013037493 | G6: ='Data Sheet'!H21/'Data Sheet'!H17 -> 0.012746403 | H6: ='Data Sheet'!I21/'Data Sheet'!I17 -> 0.011478094 | I6: ='Data Sheet'!J21/'Data Sheet'!J17 -> 0.011723965 | J6: ='Data Sheet'!K21/'Data Sheet'!K17 -> 0.013456673
B7: Employee Cost | C7: ='Data Sheet'!D22/'Data Sheet'!D17 -> 0.099416855 | D7: ='Data Sheet'!E22/'Data Sheet'!E17 -> 0.10577114 | E7: ='Data Sheet'!F22/'Data Sheet'!F17 -> 0.10643403 | F7: ='Data Sheet'!G22/'Data Sheet'!G17 -> 0.11700184 | G7: ='Data Sheet'!H22/'Data Sheet'!H17 -> 0.11731119 | H7: ='Data Sheet'!I22/'Data Sheet'!I17 -> 0.10946652 | I7: ='Data Sheet'!J22/'Data Sheet'!J17 -> 0.10157907 | J7: ='Data Sheet'!K22/'Data Sheet'!K17 -> 0.10798512
B8: Selling and admin | C8: ='Data Sheet'!D23/'Data Sheet'!D17 -> 0.0370877 | D8: ='Data Sheet'!E23/'Data Sheet'!E17 -> 0.034308653 | E8: ='Data Sheet'!F23/'Data Sheet'!F17 -> 0.037187482 | F8: ='Data Sheet'!G23/'Data Sheet'!G17 -> 0.039774406 | G8: ='Data Sheet'!H23/'Data Sheet'!H17 -> 0.038534957 | H8: ='Data Sheet'!I23/'Data Sheet'!I17 -> 0.30876204 | I8: ='Data Sheet'!J23/'Data Sheet'!J17 -> 0.31271889 | J8: ='Data Sheet'!K23/'Data Sheet'!K17 -> 0.29704108
B9: Other Expenses | C9: ='Data Sheet'!D24/'Data Sheet'!D17 -> 0.1827471 | D9: ='Data Sheet'!E24/'Data Sheet'!E17 -> 0.2213739 | E9: ='Data Sheet'!F24/'Data Sheet'!F17 -> 0.2516058 | F9: ='Data Sheet'!G24/'Data Sheet'!G17 -> 0.2462408 | G9: ='Data Sheet'!H24/'Data Sheet'!H17 -> 0.2006069 | H9: ='Data Sheet'!I24/'Data Sheet'!I17 -> 0.18441689 | I9: ='Data Sheet'!J24/'Data Sheet'!J17 -> 0.12984179 | J9: ='Data Sheet'!K24/'Data Sheet'!K17 -> 0.16564329
B10: Other Income | C10: ='Data Sheet'!D25/'Data Sheet'!D17 -> 0.18017228 | D10: ='Data Sheet'!E25/'Data Sheet'!E17 -> 0.20361007 | E10: ='Data Sheet'!F25/'Data Sheet'!F17 -> 0.21262053 | F10: ='Data Sheet'!G25/'Data Sheet'!G17 -> 0.23363123 | G10: ='Data Sheet'!H25/'Data Sheet'!H17 -> 0.19860173 | H10: ='Data Sheet'!I25/'Data Sheet'!I17 -> 0.43837892 | I10: ='Data Sheet'!J25/'Data Sheet'!J17 -> 0.40000454 | J10: ='Data Sheet'!K25/'Data Sheet'!K17 -> 0.42123144
B11: Depreciation | C11: ='Data Sheet'!D26/'Data Sheet'!D17 -> 0.011607659 | D11: ='Data Sheet'!E26/'Data Sheet'!E17 -> 0.010449115 | E11: ='Data Sheet'!F26/'Data Sheet'!F17 -> 0.010773895 | F11: ='Data Sheet'!G26/'Data Sheet'!G17 -> 0.01236409 | G11: ='Data Sheet'!H26/'Data Sheet'!H17 -> 0.013735955 | H11: ='Data Sheet'!I26/'Data Sheet'!I17 -> 0.010901078 | I11: ='Data Sheet'!J26/'Data Sheet'!J17 -> 0.011312718 | J11: ='Data Sheet'!K26/'Data Sheet'!K17 -> 0.01203304
B12: Interest | C12: ='Data Sheet'!D27/'Data Sheet'!D17 -> 0.51076752 | D12: ='Data Sheet'!E27/'Data Sheet'!E17 -> 0.50853409 | E12: ='Data Sheet'!F27/'Data Sheet'!F17 -> 0.4608828 | F12: ='Data Sheet'!G27/'Data Sheet'!G17 -> 0.43096864 | G12: ='Data Sheet'!H27/'Data Sheet'!H17 -> 0.45550861 | H12: ='Data Sheet'!I27/'Data Sheet'!I17 -> 0.54341295 | I12: ='Data Sheet'!J27/'Data Sheet'!J17 -> 0.54670632 | J12: ='Data Sheet'!K27/'Data Sheet'!K17 -> 0.53208023
B13: Profit before tax | C13: ='Data Sheet'!D28/'Data Sheet'!D17 -> 0.32634004 | D13: ='Data Sheet'!E28/'Data Sheet'!E17 -> 0.31258763 | E13: ='Data Sheet'!F28/'Data Sheet'!F17 -> 0.33290821 | F13: ='Data Sheet'!G28/'Data Sheet'!G17 -> 0.37424396 | G13: ='Data Sheet'!H28/'Data Sheet'!H17 -> 0.36015772 | H13: ='Data Sheet'!I28/'Data Sheet'!I17 -> 0.26994135 | I13: ='Data Sheet'!J28/'Data Sheet'!J17 -> 0.28612179 | J13: ='Data Sheet'!K28/'Data Sheet'!K17 -> 0.292992
B14: Tax | C14: ='Data Sheet'!D29/'Data Sheet'!D17 -> 0.11289907 | D14: ='Data Sheet'!E29/'Data Sheet'!E17 -> 0.089194315 | E14: ='Data Sheet'!F29/'Data Sheet'!F17 -> 0.085096661 | F14: ='Data Sheet'!G29/'Data Sheet'!G17 -> 0.093591408 | G14: ='Data Sheet'!H29/'Data Sheet'!H17 -> 0.089893563 | H14: ='Data Sheet'!I29/'Data Sheet'!I17 -> 0.039210782 | I14: ='Data Sheet'!J29/'Data Sheet'!J17 -> 0.067788608 | J14: ='Data Sheet'!K29/'Data Sheet'!K17 -> 0.06575156
B15: Net profit | C15: ='Data Sheet'!D30/'Data Sheet'!D17 -> 0.21236471 | D15: ='Data Sheet'!E30/'Data Sheet'!E17 -> 0.22304696 | E15: ='Data Sheet'!F30/'Data Sheet'!F17 -> 0.24762828 | F15: ='Data Sheet'!G30/'Data Sheet'!G17 -> 0.27993052 | G15: ='Data Sheet'!H30/'Data Sheet'!H17 -> 0.26937639 | H15: ='Data Sheet'!I30/'Data Sheet'!I17 -> 0.22584968 | I15: ='Data Sheet'!J30/'Data Sheet'!J17 -> 0.21046107 | J15: ='Data Sheet'!K30/'Data Sheet'!K17 -> 0.21807994
B16: Dividend Amount | C16: ='Data Sheet'!D31/'Data Sheet'!D17 -> 0.03884482 | D16: ='Data Sheet'!E31/'Data Sheet'!E17 -> 0.011218823 | E16: ='Data Sheet'!F31/'Data Sheet'!F17 -> 0.027874392 | F16: ='Data Sheet'!G31/'Data Sheet'!G17 -> 0.063231919 | G16: ='Data Sheet'!H31/'Data Sheet'!H17 -> 0.062085965 | H16: ='Data Sheet'!I31/'Data Sheet'!I17 -> 0.052226375 | I16: ='Data Sheet'!J31/'Data Sheet'!J17 -> 0.05004896 | J16: ='Data Sheet'!K31/'Data Sheet'!K17 -> 0.068441575
B21: Particulars | C21: 43555 | D21: 43921 | E21: 44286 | F21: 44651 | G21: 45016 | H21: 45382 | I21: 45747 | J21: 46112
B23: Total Liabilities | C23: ='Historical FS'!C70/'Historical FS'!C70 -> 1 | D23: ='Historical FS'!D70/'Historical FS'!D70 -> 1 | E23: ='Historical FS'!E70/'Historical FS'!E70 -> 1 | F23: ='Historical FS'!F70/'Historical FS'!F70 -> 1 | G23: ='Historical FS'!G70/'Historical FS'!G70 -> 1 | H23: ='Historical FS'!H70/'Historical FS'!H70 -> 1 | I23: ='Historical FS'!I70/'Historical FS'!I70 -> 1 | J23: ='Historical FS'!J70/'Historical FS'!J70 -> 1
B24: Equity Share Capital | C24: ='Historical FS'!C65/'Historical FS'!C70 -> 0.00042130074 | D24: ='Historical FS'!D65/'Historical FS'!D70 -> 0.000346862 | E24: ='Historical FS'!E65/'Historical FS'!E70 -> 0.00030635064 | F24: ='Historical FS'!F65/'Historical FS'!F70 -> 0.00026121863 | G24: ='Historical FS'!G65/'Historical FS'!G70 -> 0.00022050381 | H24: ='Historical FS'!H65/'Historical FS'!H70 -> 0.0001884996 | I24: ='Historical FS'!I65/'Historical FS'!I70 -> 0.00017422606 | J24: ='Historical FS'!J65/'Historical FS'!J70 -> 0.00031365804
B25: Reserves | C25: ='Historical FS'!C66/'Historical FS'!C70 -> 0.11844626 | D25: ='Historical FS'!D66/'Historical FS'!D70 -> 0.11121394 | E25: ='Historical FS'!E66/'Historical FS'!E70 -> 0.11628682 | F25: ='Historical FS'!F66/'Historical FS'!F70 -> 0.11624082 | G25: ='Historical FS'!G66/'Historical FS'!G70 -> 0.11416212 | H25: ='Historical FS'!H66/'Historical FS'!H70 -> 0.11305548 | I25: ='Historical FS'!I66/'Historical FS'!I70 -> 0.11862731 | J25: ='Historical FS'!J66/'Historical FS'!J70 -> 0.11910263
B26: Borrowings | C26: ='Historical FS'!C67/'Historical FS'!C70 -> 0.83557448 | D26: ='Historical FS'!D67/'Historical FS'!D70 -> 0.84325392 | E26: ='Historical FS'!E67/'Historical FS'!E70 -> 0.83990667 | F26: ='Historical FS'!F67/'Historical FS'!F70 -> 0.840803 | G26: ='Historical FS'!G67/'Historical FS'!G70 -> 0.84539381 | H26: ='Historical FS'!H67/'Historical FS'!H70 -> 0.77105532 | I26: ='Historical FS'!I67/'Historical FS'!I70 -> 0.76170768 | J26: ='Historical FS'!J67/'Historical FS'!J70 -> 0.751497
B27: Other Liabilities | C27: ='Historical FS'!C69/'Historical FS'!C70 -> 0.045557959 | D27: ='Historical FS'!D69/'Historical FS'!D70 -> 0.045185283 | E27: ='Historical FS'!E69/'Historical FS'!E70 -> 0.043500162 | F27: ='Historical FS'!F69/'Historical FS'!F70 -> 0.042694962 | G27: ='Historical FS'!G69/'Historical FS'!G70 -> 0.040223571 | H27: ='Historical FS'!H69/'Historical FS'!H70 -> 0.11570069 | I27: ='Historical FS'!I69/'Historical FS'!I70 -> 0.11949078 | J27: ='Historical FS'!J69/'Historical FS'!J70 -> 0.12908671
B29: Total Assets | C29: =C5 -> 1 | D29: =D5 -> 1 | E29: =E5 -> 1 | F29: =F5 -> 1 | G29: =G5 -> 1 | H29: =H5 -> 1 | I29: =I5 -> 1 | J29: =J5 -> 1
B30: Fixed Assests Net Block | C30: ='Historical FS'!C72/'Historical FS'!$C$84 -> 0.0033791853 | D30: ='Historical FS'!D72/'Historical FS'!$C$84 -> 0.0036940199 | E30: ='Historical FS'!E72/'Historical FS'!$C$84 -> 0.0040596587 | F30: ='Historical FS'!F72/'Historical FS'!$C$84 -> 0.0049752797 | G30: ='Historical FS'!G72/'Historical FS'!$C$84 -> 0.0065217456 | H30: ='Historical FS'!H72/'Historical FS'!$C$84 -> 0.0097491525 | I30: ='Historical FS'!I72/'Historical FS'!$C$84 -> 0.011802191 | J30: ='Historical FS'!J72/'Historical FS'!$C$84 -> 0.012756433
B31: Capital Work in Progress | C31: ='Historical FS'!C73/'Historical FS'!$C$84 -> 0 | D31: ='Historical FS'!D73/'Historical FS'!$C$84 -> 0 | E31: ='Historical FS'!E73/'Historical FS'!$C$84 -> 0 | F31: ='Historical FS'!F73/'Historical FS'!$C$84 -> 0 | G31: ='Historical FS'!G73/'Historical FS'!$C$84 -> 0 | H31: ='Historical FS'!H73/'Historical FS'!$C$84 -> 0 | I31: ='Historical FS'!I73/'Historical FS'!$C$84 -> 0 | J31: ='Historical FS'!J73/'Historical FS'!$C$84 -> 0
B32: Investments | C32: ='Historical FS'!C74/'Historical FS'!$C$84 -> 0.22388969 | D32: ='Historical FS'!D74/'Historical FS'!$C$84 -> 0.30113183 | E32: ='Historical FS'!E74/'Historical FS'!$C$84 -> 0.33943469 | F32: ='Historical FS'!F74/'Historical FS'!$C$84 -> 0.34751073 | G32: ='Historical FS'!G74/'Historical FS'!$C$84 -> 0.3957143 | H32: ='Historical FS'!H74/'Historical FS'!$C$84 -> 0.77790624 | I32: ='Historical FS'!I74/'Historical FS'!$C$84 -> 0.91775035 | J32: ='Historical FS'!J74/'Historical FS'!$C$84 -> 0.99026194
B33: Other Assets | C33: ='Historical FS'!C76/'Historical FS'!$C$84 -> 0.73652724 | D33: ='Historical FS'!D76/'Historical FS'!$C$84 -> 0.86210853 | E33: ='Historical FS'!E76/'Historical FS'!$C$84 -> 0.97312752 | F33: ='Historical FS'!F76/'Historical FS'!$C$84 -> 1.1890477 | G33: ='Historical FS'!G76/'Historical FS'!$C$84 -> 1.4644351 | H33: ='Historical FS'!H76/'Historical FS'!$C$84 -> 2.191505 | I33: ='Historical FS'!I76/'Historical FS'!$C$84 -> 2.3561071 | J33: ='Historical FS'!J76/'Historical FS'!$C$84 -> 2.6378955
B34: Total Non Current Assets | C34: ='Historical FS'!C77/'Historical FS'!$C$84 -> 0.96379611 | D34: ='Historical FS'!D77/'Historical FS'!$C$84 -> 1.1669344 | E34: ='Historical FS'!E77/'Historical FS'!$C$84 -> 1.3166219 | F34: ='Historical FS'!F77/'Historical FS'!$C$84 -> 1.5415337 | G34: ='Historical FS'!G77/'Historical FS'!$C$84 -> 1.8666712 | H34: ='Historical FS'!H77/'Historical FS'!$C$84 -> 2.9791604 | I34: ='Historical FS'!I77/'Historical FS'!$C$84 -> 3.2856597 | J34: ='Historical FS'!J77/'Historical FS'!$C$84 -> 3.6409139
B35: Cash & Bank | C35: ='Historical FS'!C81/'Historical FS'!$C$84 -> 0.036203886 | D35: ='Historical FS'!D81/'Historical FS'!$C$84 -> 0.055856034 | E35: ='Historical FS'!E81/'Historical FS'!$C$84 -> 0.075317079 | F35: ='Historical FS'!F81/'Historical FS'!$C$84 -> 0.10058024 | G35: ='Historical FS'!G81/'Historical FS'!$C$84 -> 0.090647248 | H35: ='Historical FS'!H81/'Historical FS'!$C$84 -> 0.13824093 | I35: ='Historical FS'!I81/'Historical FS'!$C$84 -> 0.11168751 | J35: ='Historical FS'!J81/'Historical FS'!$C$84 -> 0.15524924
B36: Total Current Assets | C36: ='Historical FS'!C82/'Historical FS'!$C$84 -> 0.036203886 | D36: ='Historical FS'!D82/'Historical FS'!$C$84 -> 0.055856034 | E36: ='Historical FS'!E82/'Historical FS'!$C$84 -> 0.075317079 | F36: ='Historical FS'!F82/'Historical FS'!$C$84 -> 0.10058024 | G36: ='Historical FS'!G82/'Historical FS'!$C$84 -> 0.090647248 | H36: ='Historical FS'!H82/'Historical FS'!$C$84 -> 0.13824093 | I36: ='Historical FS'!I82/'Historical FS'!$C$84 -> 0.11168751 | J36: ='Historical FS'!J82/'Historical FS'!$C$84 -> 0.15524924

Sheet Cash Flow statement
B2: CASH FLOW STATEMENT
C4: 42430 | D4: 42795 | E4: 43160 | F4: 43525 | G4: 43891 | J4: 44621 | K4: 44986 | L4: 45352 | M4: 45717 | N4: 46082
B5: Cash from Operating Activity - | C5: -21281 | D5: -34435 | E5: 17282 | F5: 17214 | G5: -62872 | H5: -16869 | I5: 42476 | J5: -11960 | K5: 20814 | L5: 19069 | M5: 127242 | N5: =Sheet1!N4 -> 113506
B6: Profit from operations | C6: 19196 | D6: 23481 | E6: 28573 | F6: 36737 | G6: 44497 | H6: 54764 | I6: 65619 | J6: 70781 | K6: 79722 | L6: 91618 | M6: 117642 | N6: =Sheet1!N5 -> 133545
B7: Loans Advances | C7: -70356 | D7: -106601 | E7: -101890 | F7: -120305 | G7: -176608 | H7: -185500 | I7: -155681 | J7: -248946 | K7: -254569 | L7: -312488 | M7: -169918 | N7: =Sheet1!N6 -> -340271
B8: Operating investments | C8: -45020 | D8: -39116 | E8: -17326 | F8: -28231 | G8: -51458 | H8: -101070 | I8: -50157 | J8: -10849 | K8: -64182 | L8: -88412 | M8: -180363 | N8: =Sheet1!N7 -> -102573
B9: Operating Deposits | C9: 83203 | D9: 95590 | E9: 97261 | F9: 145241 | G9: 134128 | H9: 223704 | I9: 187514 | J9: 224282 | K9: 324660 | L9: 336965 | M9: 334011 | N9: =Sheet1!N8 -> 388740
B10: Other WC items | C10: -2656 | D10: -716 | E10: 18348 | F10: -6218 | G10: -932 | H10: 2110 | I10: 8203 | J10: -32389 | K10: -48450 | L10: 14229 | M10: 45578 | N10: =Sheet1!N9 -> 56721 | Q10: 2
B11: Working capital changes | C11: -34829 | D11: -50844 | E11: -3607 | F11: -9513 | G11: -94870 | H11: -60756 | I11: -10121 | J11: -67902 | K11: -42541 | L11: -49706 | M11: 29308 | N11: =Sheet1!N10 -> 2617
B12: Direct taxes | C12: -5647 | D12: -7073 | E12: -7685 | F12: -10010 | G12: -12498 | H12: -10877 | I12: -13021 | J12: -14838 | K12: -16367 | L12: -22843 | M12: -19709 | N12: =Sheet1!N11 -> -22656
B13: Cash from Investing Activity - | C13: -800 | D13: -837 | E13: -1146 | F13: -842 | G13: -1503 | H13: -1403 | I13: -1823 | J13: -2051 | K13: -2992 | L13: 16600 | M13: -3651 | N13: =Sheet1!N12 -> 7477
B14: Fixed assets purchased | C14: -772 | D14: -877 | E14: -1158 | F14: -848 | G14: -1621 | H14: -1636 | I14: -1696 | J14: -2236 | K14: -3467 | L14: -4287 | M14: -4076 | N14: =Sheet1!N13 -> -3890
B15: Fixed assets sold | C15: 33 | D15: 12 | E15: 10 | F15: 10 | G15: 22 | H15: 19 | I15: 15 | J15: 20 | K15: 43 | L15: 100 | M15: 101 | N15: =Sheet1!N14 -> 528
B16: Investments sold | C16: 0 | D16: 0 | E16: 0 | F16: 0 | G16: 0 | H16: 0 | I16: 0 | J16: 0 | K16: 0 | L16: 9501 | M16: 192 | N16: =Sheet1!N15 -> 9806
B17: Invest in subsidiaries | C17: -72 | D17: 0 | E17: 0 | F17: 0 | G17: 0 | H17: 0 | I17: 0 | J17: 0 | K17: 0 | L17: 0 | M17: -67 | N17: =Sheet1!N16 -> -81
B18: Acquisition of companies | C18: 0 | D18: 0 | E18: 0 | F18: -14 | G18: 0 | H18: 0 | I18: 0 | J18: 0 | K18: 0 | L18: 0 | M18: 0 | N18: =Sheet1!N17 -> 0
B19: Other investing items | C19: 11 | D19: 28 | E19: 1 | F19: 11 | G19: 95 | H19: 214 | I19: -142 | J19: 165 | K19: 432 | L19: 11287 | M19: 200 | N19: =Sheet1!N18 -> 1114
B20: Cash from Financing Activity - | C20: 18694 | D20: 37815 | E20: -5893 | F20: 57378 | G20: 23131 | H20: 24394 | I20: -7321 | J20: 48124 | K20: 23941 | L20: -3983 | M20: -102478 | N20: =Sheet1!N19 -> -59005
B21: Proceeds from shares | C21: 10718 | D21: 1223 | E21: 2262 | F21: 13006 | G21: 26690 | H21: 1849 | I21: 1760 | J21: 2610 | K21: 3416 | L21: 5250 | M21: 6346 | N21: =Sheet1!N20 -> 7565
B22: Proceeds from debentures | C22: 0 | D22: 0 | E22: 0 | F22: 0 | G22: 0 | H22: 744 | I22: 356 | J22: 8313 | K22: 23000 | L22: 2350 | M22: 1182 | N22: =Sheet1!N21 -> 700
... B27: Other financing items | C27: 9625 | D27: 38601 | E27: -5746 | F27: 47203 | G27: 145 | H27: 75 | I27: 56 | J27: 136 | K27: 199 | L27: 4394 | M27: 1883 | N27: =Sheet1!N26 -> 2331
B28: Net Cash Flow | C28: -3387 | D28: 2542 | E28: 10242 | F28: 73750 | G28: -41244 | H28: 6122 | I28: 33332 | J28: =J20+J13+J5 -> 34113 | K28: =K20+K13+K5 -> 41763 | L28: =L20+L13+L5 -> 31686 | M28: =M20+M13+M5 -> 21113 | N28: =N20+N13+N5 -> 61978
B29: YoY growth | K29: =K28/J28-1 -> 0.22425468 | L29: =L28/K28-1 -> -0.24129014 | M29: =M28/L28-1 -> -0.33368049 | N29: =N28/M28-1 -> 1.9355373

Sheet Sheet1
B3: Mar 2015 | C3: 42430 | D3: 42795 | E3: 43160 | F3: 43525 | G3: 43891 | H3: 44256 | I3: 44621 | J3: 44986 | K3: 45352 | L3: 45717 | M3: 46082
B4: Cash from Operating Activity - | C4: -21281 | D4: -34435 | E4: 17282 | F4: 17214 | G4: -62872 | H4: -16869 | I4: 42476 | J4: -11960 | K4: 20814 | L4: 19069 | M4: 127242 | N4: 113506
B5: Profit from operations | C5: 19196 | D5: 23481 | E5: 28573 | F5: 36737 | G5: 44497 | H5: 54764 | I5: 65619 | J5: 70781 | K5: 79722 | L5: 91618 | M5: 117642 | N5: 133545
B6: Loans Advances | C6: -70356 | D6: -106601 | E6: -101890 | F6: -120305 | G6: -176608 | H6: -185500 | I6: -155681 | J6: -248946 | K6: -254569 | L6: -312488 | M6: -169918 | N6: -340271
B7: Operating investments | C7: -45020 | D7: -39116 | E7: -17326 | F7: -28231 | G7: -51458 | H7: -101070 | I7: -50157 | J7: -10849 | K7: -64182 | L7: -88412 | M7: -180363 | N7: -102573
B8: Operating Deposits | C8: 83203 | D8: 95590 | E8: 97261 | F8: 145241 | G8: 134128 | H8: 223704 | I8: 187514 | J8: 224282 | K8: 324660 | L8: 336965 | M8: 334011 | N8: 388740
B9: Other WC items | C9: -2656 | D9: -716 | E9: 18348 | F9: -6218 | G9: -932 | H9: 2110 | I9: 8203 | J9: -32389 | K9: -48450 | L9: 14229 | M9: 45578 | N9: 56721
B10: Working capital changes | C10: -34829 | D10: -50844 | E10: -3607 | F10: -9513 | G10: -94870 | H10: -60756 | I10: -10121 | J10: -67902 | K10: -42541 | L10: -49706 | M10: 29308 | N10: 2617
B11: Direct taxes | C11: -5647 | D11: -7073 | E11: -7685 | F11: -10010 | G11: -12498 | H11: -10877 | I11: -13021 | J11: -14838 | K11: -16367 | L11: -22843 | M11: -19709 | N11: -22656
B12: Cash from Investing Activity - | C12: -800 | D12: -837 | E12: -1146 | F12: -842 | G12: -1503 | H12: -1403 | I12: -1823 | J12: -2051 | K12: -2992 | L12: 16600 | M12: -3651 | N12: 7477
B13: Fixed assets purchased | C13: -772 | D13: -877 | E13: -1158 | F13: -848 | G13: -1621 | H13: -1636 | I13: -1696 | J13: -2236 | K13: -3467 | L13: -4287 | M13: -4076 | N13: -3890
B14: Fixed assets sold | C14: 33 | D14: 12 | E14: 10 | F14: 10 | G14: 22 | H14: 19 | I14: 15 | J14: 20 | K14: 43 | L14: 100 | M14: 101 | N14: 528
B15: Investments sold | C15: 0 | D15: 0 | E15: 0 | F15: 0 | G15: 0 | H15: 0 | I15: 0 | J15: 0 | K15: 0 | L15: 9501 | M15: 192 | N15: 9806
... B26: Other financing items | C26: 9625 | D26: 38601 | E26: -5746 | F26: 47203 | G26: 145 | H26: 75 | I26: 56 | J26: 136 | K26: 199 | L26: 4394 | M26: 1883 | N26: 2331
B27: Net Cash Flow | C27: -3387 | D27: 2542 | E27: 10242 | F27: 73750 | G27: -41244 | H27: 6122 | I27: 33332 | J27: 34113 | K27: 41762 | L27: 31687 | M27: 21113

Sheet DATA>

Sheet Data Sheet
A1: COMPANY NAME | B1: HDFC BANK LTD | E1: =IF(B2<>B3, "A NEW VERSION OF THE WORKSHEET IS AVAILABLE", "")
A2: LATEST VERSION | B2: 2.1 | E2: PLEASE DO NOT MAKE ANY CHANGES TO THIS SHEET
A3: CURRENT VERSION | B3: 2.1
A5: META
A6: Number of shares | B6: =IF(B9>0, B9/B8, 0) -> 1539.1484
A7: Face Value | B7: 1
A8: Current Price | B8: 710.5
A9: Market Capitalization | B9: 1093564.9
A15: PROFIT & LOSS
A16: Report Date | B16: 42825 | C16: 43190 | D16: 43555 | E16: 43921 | F16: 44286 | G16: 44651 | H16: 45016 | I16: 45382 | J16: 45747 | K16: 46112
A17: Sales | B17: 73271.35 | C17: 85287.84 | D17: 105160.74 | E17: 122189.29 | F17: 128552.4 | G17: 135936.41 | H17: 170754.05 | I17: 283649.02 | J17: 336367.43 | K17: 348615.15
A18: Raw Material Cost
A19: Change in Inventory
A20: Power and Fuel
A21: Other Mfr. Exp | B21: 1271.8 | C21: 1314.97 | D21: 1283.53 | E21: 1293.44 | F21: 1649.11 | G21: 1772.27 | H21: 2176.5 | I21: 3255.75 | J21: 3943.56 | K21: 4691.2
A22: Employee Cost | B22: 8508.22 | C22: 9197.15 | D22: 10454.75 | E22: 12924.1 | F22: 13682.35 | G22: 15904.81 | H22: 20031.36 | I22: 31050.07 | J22: 34167.89 | K22: 37645.25
A23: Selling and admin | B23: 3328.39 | C23: 3658.43 | D23: 3900.17 | E23: 4192.15 | F23: 4780.54 | G23: 5406.79 | H23: 6580 | I23: 87580.05 | J23: 105188.45 | K23: 103553.02
A24: Other Expenses | B24: 10747.28 | C24: 15361.71 | D24: 19217.82 | E24: 27049.52 | F24: 32344.53 | G24: 33473.09 | H24: 34254.44 | I24: 52309.67 | J24: 43674.55 | K24: 57745.76
A25: Other Income | B25: 12905.08 | C25: 16056.6 | D25: 18947.05 | E25: 24878.97 | F25: 27332.88 | G25: 31758.99 | H25: 33912.05 | I25: 124345.75 | J25: 134548.5 | K25: 146847.66
A26: Depreciation | B26: 886.19 | C26: 966.78 | D26: 1220.67 | E26: 1276.77 | F26: 1385.01 | G26: 1680.73 | H26: 2345.47 | I26: 3092.08 | J26: 3805.23 | K26: 4194.9
A27: Interest | B27: 38041.58 | C27: 42381.48 | D27: 53712.69 | E27: 62137.42 | F27: 59247.59 | G27: 58584.33 | H27: 77779.94 | I27: 154138.55 | J27: 183894.2 | K27: 185491.23
A28: Profit before tax | B28: 23392.97 | C28: 28463.92 | D28: 34318.16 | E28: 38194.86 | F28: 42796.15 | G28: 50873.38 | H28: 61498.39 | I28: 76568.6 | J28: 96242.05 | K28: 102141.45
A29: Tax | B29: 8078.12 | C29: 9903.08 | D29: 11872.55 | E29: 10898.59 | F29: 10939.38 | G29: 12722.48 | H29: 15349.69 | I29: 11122.1 | J29: 22801.88 | K29: 22921.99
A30: Net profit | B30: 15280.48 | C30: 18510.02 | D30: 22332.43 | E30: 27253.95 | F30: 31833.21 | G30: 38052.75 | H30: 45997.11 | I30: 64062.04 | J30: 70792.25 | K30: 76025.97
A31: Dividend Amount | B31: 2818.8 | C31: 3373.63 | D31: 4084.95 | E31: 1370.82 | F31: 3583.32 | G31: 8595.52 | H31: 10601.43 | I31: 14813.96 | J31: 16834.84 | K31: 23859.77
A40: Quarters
A41: Report Date | B41: 45382 | C41: 45473 | D41: 45565 | E41: 45657 | F41: 45747 | G41: 45838 | H41: 45930 | I41: 46022 | J41: 46112 | K41: 46203
A42: Sales | B42: 79433.61 | C42: 81546.2 | D42: 83001.72 | E42: 85040.17 | F42: 86779.34 | G42: 87371.87 | H42: 86993.84 | I42: 87066.94 | J42: 87182.5 | K42: 90575.33
A43: Expenses | B43: 62938.45 | C43: 49689.62 | D43: 52074.11 | E43: 41306.79 | F43: 47709.16 | G43: 64496.63 | H43: 45160.88 | I43: 54144.75 | J43: 44027.87 | K43: 58291.57
A44: Other Income | B44: 44957.74 | C44: 35450.29 | D44: 38455.02 | E44: 27153.77 | F44: 33489.42 | G44: 45683.1 | H44: 31566.79 | I44: 39860.33 | J44: 29737.44 | K44: 42535.03
A45: Depreciation
A46: Interest | B46: 43691.51 | C46: 44579.5 | D46: 45414.21 | E46: 46914.28 | F46: 46986.21 | G46: 47708.51 | H46: 46740.86 | I46: 45821.42 | J46: 45220.44 | K46: 47625.63
A47: Profit before tax | B47: 17761.39 | C47: 22727.37 | D47: 23968.42 | E47: 23972.87 | F47: 25573.39 | G47: 20849.83 | H47: 26658.89 | I47: 26961.1 | J47: 27671.63 | K47: 27193.16
A48: Tax | B48: -251.48 | C48: 5539.32 | D48: 5340.98 | E48: 5632.76 | F48: 6288.82 | G48: 3759.4 | H48: 6295.12 | I48: 6270.06 | J48: 6597.41 | K48: 6810.47
A49: Net profit | B49: 17622.38 | C49: 16474.85 | D49: 17825.91 | E49: 17656.61 | F49: 18834.88 | G49: 16257.91 | H49: 19610.67 | I49: 19806.63 | J49: 20350.76 | K49: 19244.71
A50: Operating Profit | B50: 16495.16 | C50: 31856.58 | D50: 30927.61 | E50: 43733.38 | F50: 39070.18 | G50: 22875.24 | H50: 41832.96 | I50: 32922.19 | J50: 43154.63 | K50: 32283.76
A55: BALANCE SHEET
A56: Report Date | B56: 42825 | C56: 43190 | D56: 43555 | E56: 43921 | F56: 44286 | G56: 44651 | H56: 45016 | I56: 45382 | J56: 45747 | K56: 46112
A57: Equity Share Capital | B57: 512.51 | C57: 519.02 | D57: 544.66 | E57: 548.33 | F57: 551.28 | G57: 554.55 | H57: 557.97 | I57: 759.69 | J57: 765.22 | K57: 1539.34
A58: Reserves | B58: 91281.44 | C58: 109080.11 | D58: 153128 | E58: 175810.38 | F58: 209258.9 | G58: 246771.62 | H58: 288879.53 | I58: 455635.56 | J58: 521024.17 | K58: 584520.13
...
